<sdf version='1.6'>
  <world name='default'>
    <light name='sun' type='directional'>
      <cast_shadows>1</cast_shadows>
      <pose frame=''>0 0 10 0 -0 0</pose>
      <diffuse>0.8 0.8 0.8 1</diffuse>
      <specular>0.1 0.1 0.1 1</specular>
      <attenuation>
        <range>1000</range>
        <constant>0.9</constant>
        <linear>0.01</linear>
        <quadratic>0.001</quadratic>
      </attenuation>
      <direction>-0.5 0.5 -1</direction>
    </light>
    <gravity>0 0 -9.8</gravity>
    <magnetic_field>6e-06 2.3e-05 -4.2e-05</magnetic_field>
    <atmosphere type='adiabatic'/>
    <physics name='default_physics' default='0' type='ode'>
      <max_step_size>0.001</max_step_size>
      <real_time_factor>1</real_time_factor>
      <real_time_update_rate>1000</real_time_update_rate>
    </physics>
    <scene>
      <ambient>0.6 0.6 0.6 1</ambient>
      <background>0.9 0.9 0.9 1</background>
      <shadows>0</shadows>
    </scene>
    <spherical_coordinates>
      <surface_model>EARTH_WGS84</surface_model>
      <latitude_deg>0</latitude_deg>
      <longitude_deg>0</longitude_deg>
      <elevation>0</elevation>
      <heading_deg>0</heading_deg>
    </spherical_coordinates>
    <model name='alfombra'>
      <static>1</static>
      <link name='link'>
        <collision name='collision'>
          <geometry>
            <plane>
              <normal>0 0 1</normal>
              <size>100 100</size>
            </plane>
          </geometry>
          <surface>
            <friction>
              <ode>
                <mu>100</mu>
                <mu2>50</mu2>
              </ode>
              <torsional>
                <ode/>
              </torsional>
            </friction>
            <contact>
              <ode/>
            </contact>
            <bounce/>
          </surface>
          <max_contacts>10</max_contacts>
        </collision>
        <visual name='visual'>
          <cast_shadows>0</cast_shadows>
          <geometry>
            <plane>
              <normal>0 0 1</normal>
              <size>3 3</size>
            </plane>
          </geometry>
          <material>
            <script>
              <uri>model://alfombra/materials/scripts</uri>
              <uri>model://alfombra/materials/textures/</uri>
              <name>alfombra/Image</name>
            </script>
          </material>
        </visual>
        <self_collide>0</self_collide>
        <kinematic>0</kinematic>
      </link>
      <pose frame=''>-0.020893 0.019058 0 0 -0 0</pose>
    </model>
    <model name='pibot'>
      <link name='chasis'>
        <pose frame=''>0 0 0 0 -0 0</pose>
        <inertial>
          <mass>10</mass>
          <inertia>
            <ixx>1</ixx>
            <ixy>0</ixy>
            <iyy>1</iyy>
            <ixz>0</ixz>
            <iyz>0</iyz>
            <izz>1</izz>
          </inertia>
        </inertial>
        <collision name='collision'>
          <geometry>
            <mesh>
              <uri>model://pibot/meshes/chasis.dae</uri>
            </mesh>
          </geometry>
          <max_contacts>10</max_contacts>
          <surface>
            <contact>
              <ode/>
            </contact>
            <bounce/>
            <friction>
              <torsional>
                <ode/>
              </torsional>
              <ode/>
            </friction>
          </surface>
        </collision>
        <visual name='visual'>
          <geometry>
            <mesh>
              <uri>model://pibot/meshes/chasis.dae</uri>
            </mesh>
          </geometry>
        </visual>
        <self_collide>0</self_collide>
        <kinematic>0</kinematic>
      </link>
      <link name='us'>
        <pose frame=''>0 0 0 0 -0 0</pose>
        <inertial>
          <mass>0.05</mass>
          <inertia>
            <ixx>1</ixx>
            <ixy>0</ixy>
            <iyy>1</iyy>
            <ixz>0</ixz>
            <iyz>0</iyz>
            <izz>1</izz>
          </inertia>
        </inertial>
        <collision name='collision'>
          <geometry>
            <mesh>
              <uri>model://pibot/meshes/us_sensor.dae</uri>
            </mesh>
          </geometry>
          <max_contacts>10</max_contacts>
          <surface>
            <contact>
              <ode/>
            </contact>
            <bounce/>
            <friction>
              <torsional>
                <ode/>
              </torsional>
              <ode/>
            </friction>
          </surface>
        </collision>
        <visual name='visual'>
          <geometry>
            <mesh>
              <uri>model://pibot/meshes/us_sensor.dae</uri>
            </mesh>
          </geometry>
        </visual>
        <sensor name='sonar' type='sonar'>
          <pose frame=''>0.083 -0.004 0.058 0 -1.5707 0</pose>
          <sonar>
            <min>0.03</min>
            <max>4</max>
            <radius>0.01</radius>
          </sonar>
          <always_on>1</always_on>
          <update_rate>30</update_rate>
          <visualize>1</visualize>
          <plugin name='camera_dump' filename='libsonarMBOT.so'/>
        </sensor>
        <self_collide>0</self_collide>
        <kinematic>0</kinematic>
      </link>
      <link name='picam'>
        <pose frame=''>0.066 0.01 0.053 0 -0 0</pose>
        <inertial>
          <mass>0.01</mass>
          <inertia>
            <ixx>1</ixx>
            <ixy>0</ixy>
            <iyy>1</iyy>
            <ixz>0</ixz>
            <iyz>0</iyz>
            <izz>1</izz>
          </inertia>
        </inertial>
        <collision name='collision'>
          <geometry>
            <mesh>
              <uri>model://pibot/meshes/picam.dae</uri>
            </mesh>
          </geometry>
          <max_contacts>10</max_contacts>
          <surface>
            <contact>
              <ode/>
            </contact>
            <bounce/>
            <friction>
              <torsional>
                <ode/>
              </torsional>
              <ode/>
            </friction>
          </surface>
        </collision>
        <visual name='visual'>
          <geometry>
            <mesh>
              <uri>model://pibot/meshes/picam.dae</uri>
            </mesh>
          </geometry>
        </visual>
        <sensor name='picam' type='camera'>
          <pose frame=''>0.072 0.012 0.106 0 -0 0</pose>
          <camera name='__default__'>
            <horizontal_fov>1.047</horizontal_fov>
            <image>
              <width>640</width>
              <height>480</height>
            </image>
            <clip>
              <near>0.1</near>
              <far>10</far>
            </clip>
          </camera>
          <always_on>1</always_on>
          <plugin name='camera_dump' filename='libcamera_dumpMBOT.so'/>
          <update_rate>30</update_rate>
        </sensor>
        <self_collide>0</self_collide>
        <kinematic>0</kinematic>
      </link>
      <link name='ir'>
        <pose frame=''>0.056 0 0.01 0 -0 0</pose>
        <inertial>
          <mass>0.0001</mass>
          <inertia>
            <ixx>1</ixx>
            <ixy>0</ixy>
            <iyy>1</iyy>
            <ixz>0</ixz>
            <iyz>0</iyz>
            <izz>1</izz>
          </inertia>
        </inertial>
        <visual name='visual_L'>
          <pose frame=''>0 0.007 0 0 -0 0</pose>
          <geometry>
            <sphere>
              <radius>0.001</radius>
            </sphere>
          </geometry>
        </visual>
        <visual name='visual_R'>
          <pose frame=''>0 -0.007 0 0 -0 0</pose>
          <geometry>
            <sphere>
              <radius>0.001</radius>
            </sphere>
          </geometry>
        </visual>
        <sensor name='irLeft' type='camera'>
          <pose frame=''>0 0.007 0 0 1.5707 0</pose>
          <camera name='__default__'>
            <horizontal_fov>1.047</horizontal_fov>
            <image>
              <width>4</width>
              <height>4</height>
            </image>
            <clip>
              <near>0.0001</near>
              <far>0.2</far>
            </clip>
          </camera>
          <always_on>1</always_on>
          <plugin name='camera_dump' filename='libirMBOT.so'/>
          <update_rate>30</update_rate>
        </sensor>
        <sensor name='irRight' type='camera'>
          <pose frame=''>0 -0.007 0 0 1.5707 0</pose>
          <camera name='__default__'>
            <horizontal_fov>1.047</horizontal_fov>
            <image>
              <width>4</width>
              <height>4</height>
            </image>
            <clip>
              <near>0.0001</near>
              <far>0.2</far>
            </clip>
          </camera>
          <always_on>1</always_on>
          <plugin name='camera_dump' filename='libirMBOT.so'/>
          <update_rate>30</update_rate>
        </sensor>
        <self_collide>0</self_collide>
        <kinematic>0</kinematic>
      </link>
      <link name='ball'>
        <pose frame=''>-0.064 0 0.012 0 -0 0</pose>
        <inertial>
          <mass>2</mass>
          <inertia>
            <ixx>1</ixx>
            <ixy>0</ixy>
            <iyy>1</iyy>
            <ixz>0</ixz>
            <iyz>0</iyz>
            <izz>1</izz>
          </inertia>
        </inertial>
        <collision name='collision'>
          <pose frame=''>0 0 0 0 -0 0</pose>
          <geometry>
            <mesh>
              <uri>model://pibot/meshes/ball.dae</uri>
            </mesh>
          </geometry>
          <max_contacts>10</max_contacts>
          <surface>
            <contact>
              <ode/>
            </contact>
            <bounce/>
            <friction>
              <torsional>
                <ode/>
              </torsional>
              <ode/>
            </friction>
          </surface>
        </collision>
        <visual name='visual'>
          <geometry>
            <mesh>
              <uri>model://pibot/meshes/ball.dae</uri>
            </mesh>
          </geometry>
        </visual>
        <self_collide>0</self_collide>
        <kinematic>0</kinematic>
      </link>
      <link name='left_wheel'>
        <pose frame=''>0.032 -0.052 0.033 0 -0 0</pose>
        <inertial>
          <mass>0.08</mass>
          <inertia>
            <ixx>1</ixx>
            <ixy>0</ixy>
            <iyy>1</iyy>
            <ixz>0</ixz>
            <iyz>0</iyz>
            <izz>1</izz>
          </inertia>
        </inertial>
        <collision name='collision'>
          <pose frame=''>0 0 0 0 -0 0</pose>
          <geometry>
            <mesh>
              <uri>model://pibot/meshes/left_wheel.dae</uri>
            </mesh>
          </geometry>
          <max_contacts>10</max_contacts>
          <surface>
            <contact>
              <ode/>
            </contact>
            <bounce/>
            <friction>
              <torsional>
                <ode/>
              </torsional>
              <ode/>
            </friction>
          </surface>
        </collision>
        <visual name='visual'>
          <geometry>
            <mesh>
              <uri>model://pibot/meshes/left_wheel.dae</uri>
            </mesh>
          </geometry>
        </visual>
        <self_collide>0</self_collide>
        <kinematic>0</kinematic>
      </link>
      <link name='right_wheel'>
        <pose frame=''>0.032 0.052 0.033 0 -0 0</pose>
        <inertial>
          <mass>0.08</mass>
          <inertia>
            <ixx>1</ixx>
            <ixy>0</ixy>
            <iyy>1</iyy>
            <ixz>0</ixz>
            <iyz>0</iyz>
            <izz>1</izz>
          </inertia>
        </inertial>
        <collision name='collision'>
          <pose frame=''>0 0 0 0 -0 0</pose>
          <geometry>
            <mesh>
              <uri>model://pibot/meshes/right_wheel.dae</uri>
            </mesh>
          </geometry>
          <max_contacts>10</max_contacts>
          <surface>
            <contact>
              <ode/>
            </contact>
            <bounce/>
            <friction>
              <torsional>
                <ode/>
              </torsional>
              <ode/>
            </friction>
          </surface>
        </collision>
        <visual name='visual'>
          <geometry>
            <mesh>
              <uri>model://pibot/meshes/right_wheel.dae</uri>
            </mesh>
          </geometry>
        </visual>
        <self_collide>0</self_collide>
        <kinematic>0</kinematic>
      </link>
      <joint name='ball' type='revolute'>
        <pose frame=''>0 0 0 0 -0 0</pose>
        <child>ball</child>
        <parent>chasis</parent>
        <axis>
          <xyz>1 1 1</xyz>
          <use_parent_model_frame>0</use_parent_model_frame>
          <limit>
            <lower>-1e+16</lower>
            <upper>1e+16</upper>
          </limit>
          <dynamics>
            <spring_reference>0</spring_reference>
            <spring_stiffness>0</spring_stiffness>
          </dynamics>
        </axis>
      </joint>
      <joint name='right_wheel_hinge' type='revolute'>
        <pose frame=''>0 0 0 0 -0 0</pose>
        <child>right_wheel</child>
        <parent>chasis</parent>
        <axis>
          <xyz>0 1 0</xyz>
          <use_parent_model_frame>0</use_parent_model_frame>
          <limit>
            <lower>-1e+16</lower>
            <upper>1e+16</upper>
          </limit>
          <dynamics>
            <spring_reference>0</spring_reference>
            <spring_stiffness>0</spring_stiffness>
          </dynamics>
        </axis>
      </joint>
      <joint name='left_wheel_hinge' type='revolute'>
        <pose frame=''>0 0 0 0 -0 0</pose>
        <child>left_wheel</child>
        <parent>chasis</parent>
        <axis>
          <xyz>0 1 0</xyz>
          <use_parent_model_frame>0</use_parent_model_frame>
          <limit>
            <lower>-1e+16</lower>
            <upper>1e+16</upper>
          </limit>
          <dynamics>
            <spring_reference>0</spring_reference>
            <spring_stiffness>0</spring_stiffness>
          </dynamics>
        </axis>
      </joint>
      <joint name='us_fix' type='revolute'>
        <pose frame=''>0 0 0 0 -0 0</pose>
        <child>us</child>
        <parent>chasis</parent>
        <axis>
          <xyz>0 0 0</xyz>
          <use_parent_model_frame>0</use_parent_model_frame>
          <limit>
            <lower>-1e+16</lower>
            <upper>1e+16</upper>
          </limit>
          <dynamics>
            <spring_reference>0</spring_reference>
            <spring_stiffness>0</spring_stiffness>
          </dynamics>
        </axis>
      </joint>
      <joint name='ir_fix' type='revolute'>
        <pose frame=''>0 0 0 0 -0 0</pose>
        <child>ir</child>
        <parent>chasis</parent>
        <axis>
          <xyz>0 0 0</xyz>
          <use_parent_model_frame>0</use_parent_model_frame>
          <limit>
            <lower>-1e+16</lower>
            <upper>1e+16</upper>
          </limit>
          <dynamics>
            <spring_reference>0</spring_reference>
            <spring_stiffness>0</spring_stiffness>
          </dynamics>
        </axis>
      </joint>
      <joint name='picam_fix' type='revolute'>
        <pose frame=''>0 0 0 0 -0 0</pose>
        <child>picam</child>
        <parent>chasis</parent>
        <axis>
          <xyz>0 0 1</xyz>
          <use_parent_model_frame>0</use_parent_model_frame>
          <limit>
            <lower>-1e+16</lower>
            <upper>1e+16</upper>
          </limit>
          <dynamics>
            <spring_reference>0</spring_reference>
            <spring_stiffness>0</spring_stiffness>
          </dynamics>
        </axis>
      </joint>
      <plugin name='carMotors' filename='libmotorsMBOT.so'/>
      <plugin name='pose3d' filename='libpose3dMBOT.so'/>
      <pose frame=''>-0.192988 -0.438008 0 0 -0 0</pose>
    </model>
    <state world_name='default'>
      <sim_time>124 573000000</sim_time>
      <real_time>141 942493878</real_time>
      <wall_time>1558393727 995763416</wall_time>
      <iterations>124573</iterations>
      <model name='alfombra'>
        <pose frame=''>-0.020893 0.019058 0 0 -0 0</pose>
        <scale>1 1 1</scale>
        <link name='link'>
          <pose frame=''>-0.020893 0.019058 0 0 -0 0</pose>
          <velocity>0 0 0 0 -0 0</velocity>
          <acceleration>0 0 0 0 -0 0</acceleration>
          <wrench>0 0 0 0 -0 0</wrench>
        </link>
      </model>
      <model name='pibot'>
        <pose frame=''>-0.180528 -0.643982 -0.000203 0.000315 0.010271 1.63165</pose>
        <scale>1 1 1</scale>
        <link name='ball'>
          <pose frame=''>-0.17664 -0.707737 0.012451 -0.009633 0.000329 1.6218</pose>
          <velocity>1e-06 1e-06 0.004468 -7e-05 4.7e-05 -0</velocity>
          <acceleration>-0.000939 0.051372 9.38481 -0.069538 0.047054 0.000368</acceleration>
          <wrench>-0.001878 0.102745 18.7696 0 -0 0</wrench>
        </link>
        <link name='chasis'>
          <pose frame=''>-0.180528 -0.643982 -0.000203 0.000315 0.010271 1.63165</pose>
          <velocity>-1e-06 -2e-06 0.004876 -7.4e-05 4.2e-05 -5e-06</velocity>
          <acceleration>-0.003 0.048424 9.79275 -0.074453 0.042178 -0.004702</acceleration>
          <wrench>-0.030002 0.48424 97.9275 0 -0 0</wrench>
        </link>
        <link name='ir'>
          <pose frame=''>-0.183937 -0.587986 0.009221 -0.006578 0.010272 1.63165</pose>
          <velocity>-1e-06 -1e-06 0.004931 -0.000112 -7e-06 0</velocity>
          <acceleration>-0.002272 0.049229 9.84816 -0.111725 -0.006812 -0.000455</acceleration>
          <wrench>0 5e-06 0.000985 0 -0 0</wrench>
        </link>
        <link name='left_wheel'>
          <pose frame=''>-0.130581 -0.608542 0.032481 0.000315 -0.019458 1.63164</pose>
          <velocity>2e-06 -3e-06 0.010138 8.9e-05 6e-05 1e-06</velocity>
          <acceleration>0.000435 0.047623 15.0554 0.088641 0.060241 0.00132</acceleration>
          <wrench>3.5e-05 0.00381 1.20443 0 -0 0</wrench>
        </link>
        <link name='picam'>
          <pose frame=''>-0.19454 -0.578172 0.05212 0.000299 0.010272 1.63002</pose>
          <velocity>3e-06 2e-06 0.004933 -9.3e-05 7.6e-05 -1e-06</velocity>
          <acceleration>0.001024 0.052238 9.84957 -0.093031 0.07595 -0.000809</acceleration>
          <wrench>1e-05 0.000522 0.098496 0 -0 0</wrench>
        </link>
        <link name='right_wheel'>
          <pose frame=''>-0.234388 -0.614866 0.032512 0.000315 -0.016349 1.63164</pose>
          <velocity>3e-06 1e-06 0.010854 -2.8e-05 7.9e-05 -3e-06</velocity>
          <acceleration>0.000984 0.051389 15.7707 -0.027541 0.078839 -0.002658</acceleration>
          <wrench>7.9e-05 0.004111 1.26165 0 -0 0</wrench>
        </link>
        <link name='us'>
          <pose frame=''>-0.180528 -0.643982 -0.000203 -0.006578 0.010272 1.63165</pose>
          <velocity>-2e-06 -2e-06 0.004936 -0.000135 -8e-06 1e-06</velocity>
          <acceleration>-0.003118 0.048292 9.85341 -0.135384 -0.00824 0.000903</acceleration>
          <wrench>-0.000156 0.002415 0.492671 0 -0 0</wrench>
        </link>
      </model>
      <light name='sun'>
        <pose frame=''>0 0 10 0 -0 0</pose>
      </light>
    </state>
    <gui fullscreen='0'>
      <camera name='user_camera'>
        <pose frame=''>3.12934 -3.24462 1.68622 0 0.275643 2.35619</pose>
        <view_controller>orbit</view_controller>
        <projection_type>perspective</projection_type>
      </camera>
    </gui>
  </world>
</sdf>
